Workbook

Sheet 奖品配置
A1: 奖品ID | B1: 奖品名称 | C1: 图标 | D1: 总库存 | E1: 已发数量 | F1: 剩余库存 | G1: 中奖权重 | H1: 奖品价值(RM) | I1: 是否大奖 | J1: 状态 | K1: 照片链接
A2: P001 | B2: 200元霸王餐 | C2: 👑 | D2: 2 | E2: 0 | F2: =D2-E2 -> 2 | G2: 1 | I2: 是 | J2: 启用
A3: P002 | B3: 特级肥牛 | C3: 🥩 | D3: 15 | E3: 3 | F3: =D3-E3 -> 12 | G3: 5 | I3: 是 | J3: 启用
A4: P003 | B4: 西瓜小火锅 | C4: 🍉 | D4: 15 | E4: 5 | F4: =D4-E4 -> 10 | G4: 8 | I4: 否 | J4: 启用
A5: P004 | B5: 厚切牛乳冰 | C5: 🍨 | D5: 15 | E5: 5 | F5: =D5-E5 -> 10 | G5: 8 | I5: 否 | J5: 启用
A6: P005 | B6: 多巴胺绵绵冰 | C6: 🍧 | D6: 25 | E6: 6 | F6: =D6-E6 -> 19 | G6: 10 | I6: 否 | J6: 启用
A7: P006 | B7: 蜜桃爆柠茶霸王桶 | C7: 🍑 | D7: 20 | E7: 4 | F7: =D7-E7 -> 16 | G7: 10 | I7: 否 | J7: 启用
A8: P007 | B8: 五花肉 | C8: 🥓 | D8: 60 | E8: 11 | F8: =D8-E8 -> 49 | G8: 25 | I8: 否 | J8: 启用
A9: P008 | B9: 暴打柠檬茶 | C9: 🍋 | D9: 50 | E9: 12 | F9: =D9-E9 -> 38 | G9: 30 | I9: 否 | J9: 启用
A10: P009 | B10: 老式红糖冰豆花 | C10: 🍮 | D10: 50 | E10: 1 | F10: =D10-E10 -> 49 | G10: 25 | I10: 否 | J10: 启用
A11: P010 | B11: 5元代金券 | C11: 🎫 | D11: 100 | E11: 20 | F11: =D11-E11 -> 80 | G11: 40 | I11: 否 | J11: 启用
A12: P011 | B12: 10元代金券 | C12: 🎟️ | D12: 80 | E12: 16 | F12: =D12-E12 -> 64 | G12: 35 | I12: 否 | J12: 启用
A13: P012 | B13: 招牌炒饭 | C13: 🎁 | D13: 20 | E13: 0 | F13: =D13-E13 -> 20 | G13: 10 | I13: 否 | J13: 启用 | K13: 12
A14: P013 | B14: 招牌嫩牛肉 | C14: 🎁 | D14: 20 | E14: 0 | F14: =D14-E14 -> 20 | G14: 10 | I14: 否 | J14: 启用 | K14: 13
A15: P013 | B15: 招牌嫩牛肉 | C15: 🎁 | D15: 20 | E15: 0 | F15: =D15-E15 -> 20 | G15: 10 | I15: 否 | J15: 停用 | K15: 14
A16: P015 | B16: 鸭血 | C16: 🎁 | D16: 20 | E16: 0 | F16: =D16-E16 -> 20 | G16: 10 | H16: 9 | I16: 否 | J16: 启用 | K16: 15

Sheet 用户数据
A1: 用户ID | B1: 手机号 | C1: 姓名 | D1: 邮箱 | E1: 注册时间 | F1: 剩余积分 | G1: 总获得积分 | H1: 邀请码 | I1: 邀请人手机 | J1: 邀请人数 | K1: 总抽奖次数 | L1: 今日抽奖 | M1: 最后抽奖时间 | N1: 状态
A2: U001 | B2: 60123456789 | C2: 张三 | D2: zhang@test.com | E2: 46046.669 | F2: 2 | G2: 5 | H2: ABC123 | J2: 3 | K2: 8 | L2: 1 | M2: 46049.438 | N2: 正常
A3: U002 | B3: 60198765432 | C3: 李四 | D3: li@test.com | E3: 46046.669 | F3: 0 | G3: 2 | H3: DEF456 | I3: 60123456789 | J3: 0 | K3: 2 | L3: 0 | M3: 46047.632 | N3: 正常
A4: U003 | B4: 60112233445 | C4: 王五 | D4: wang@test.com | E4: 46047.417 | F4: 1 | G4: 1 | H4: GHI789 | I4: 60123456789 | J4: 0 | K4: 1 | L4: 1 | M4: 46049.458 | N4: 正常
A5: U004 | B5: 65912345678 | C5: Rachel | D5: rachel@test.com | E5: 46047.625 | F5: 0 | G5: 2 | H5: JKL012 | I5: 60123456789 | J5: 0 | K5: 2 | L5: 0 | M5: 46047.632 | N5: 正常
A6: U0005 | B6: 60167229332 | D6: it.secure00@gmail.com | E6: 46054.252 | F6: 996 | G6: 46084.252 | H6: 1 | I6: EZBCYE | K6: 0 | L6: 4 | M6: 0 | N6: 46055.889 | O6: 正常
A7: U0006 | B7: 60167826207 | D7: nicolelim106@gmail.com | E7: 46054.259 | F7: 0 | G7: 46084.259 | H7: 1 | I7: HX4EWR | K7: 0 | L7: 1 | M7: 0 | N7: 46054.259 | O7: 正常
A8: U0007 | B8: 60167229331 | D8: it.secure00@gmail.com | E8: 46054.271 | F8: 0 | G8: 46084.271 | H8: 1 | I8: V78S2A | K8: 0 | L8: 1 | M8: 0 | N8: 46054.271 | O8: 正常
A9: U0008 | B9: 60167997281 | E9: 46055.888 | F9: 0 | G9: 46085.888 | H9: 1 | I9: XLCGK8 | K9: 0 | L9: 1 | M9: 0 | N9: 46055.888 | O9: 正常
A10: U0009 | B10: 60127119900 | E10: 46058.954 | F10: 0 | G10: 46088.954 | H10: 1 | I10: QYE5EM | K10: 0 | L10: 1 | M10: 0 | N10: 46058.954 | O10: 正常
A11: U0010 | B11: 60127073822 | E11: 46059.045 | F11: 0 | G11: 46089.045 | H11: 1 | I11: 374MF9 | K11: 0 | L11: 1 | M11: 0 | N11: 46059.045 | O11: 正常

Sheet 中奖记录
A1: 记录ID | B1: 抽奖时间 | C1: 用户ID | D1: 手机号 | E1: 姓名 | F1: 奖品 | G1: 验证码 | H1: 有效期至 | I1: WA发送状态 | J1: WA发送时间 | K1: 核销状态 | L1: 核销时间 | M1: 核销员 | N1: 备注
A2: R001 | B2: 46047.63 | C2: U004 | D2: 60109890913 | E2: Rachel | F2: 多巴胺绵绵冰 | G2: ZCH436890 | H2: 46077 | I2: 已发送 | J2: 46048.63 | K2: 未核销
A3: R002 | B3: 46047.632 | C3: U002 | D3: 60198765432 | E3: 李四 | F3: 蜜桃爆柠茶霸王桶 | G3: ZCH883862 | H3: 46077 | I3: 已发送 | J3: 46048.632 | K3: 未核销
A4: R003 | B4: 46049.441 | C4: U001 | D4: 60123456789 | E4: 张三 | F4: 特级肥牛 | G4: ZCH954787 | H4: 46079 | I4: 已发送 | J4: 46050.441 | K4: 已核销 | L4: 46049.5 | M4: Boss
A5: R004 | B5: 46049.46 | C5: U003 | D5: 60112233445 | E5: 王五 | F5: 五花肉 | G5: ZCH486119 | H5: 46079 | I5: 待发送 | K5: 未核销
A6: R0005 | B6: 46054.252 | C6: U0005 | D6: 60167229332 | F6: 五花肉 | G6: ZCH329639 | H6: 46084.252 | I6: 已发送 | J6: 46054.253 | K6: 未核销
A7: R0006 | B7: 46054.259 | C7: U0006 | D7: 60167826207 | F7: 多巴胺绵绵冰 | G7: ZCH727226 | H7: 46084.259 | I7: 已发送 | J7: 46054.259 | K7: 未核销
A8: R0007 | B8: 46054.264 | C8: U0005 | D8: 60167229332 | F8: 暴打柠檬茶 | G8: ZCH554855 | H8: 46084.264 | I8: 待发送 | K8: 未核销
A9: R0008 | B9: 46054.264 | C9: U0005 | D9: 60167229332 | F9: 暴打柠檬茶 | G9: ZCH675231 | H9: 46084.264 | I9: 待发送 | K9: 未核销
A10: R0009 | B10: 46054.271 | C10: U0007 | D10: 60167229331 | F10: 蜜桃爆柠茶霸王桶 | G10: ZCH498452 | H10: 46084.271 | I10: 待发送 | K10: 未核销
A11: R0010 | B11: 46055.888 | C11: U0008 | D11: 60167997281 | F11: 五花肉 | G11: ZCH437192 | H11: 46085.888 | I11: 已发送 | J11: 46055.891 | K11: 未核销
A12: R0011 | B12: 46055.889 | C12: U0005 | D12: 60167229332 | F12: 老式红糖冰豆花 | G12: ZCH691275 | H12: 46085.889 | I12: 待发送 | K12: 未核销
A13: R0012 | B13: 46058.954 | C13: U0009 | D13: 60127119900 | F13: 10元代金券 | G13: ZCH744342 | H13: 46088.954 | I13: 已发送 | J13: 46058.955 | K13: 未核销
A14: R0013 | B14: 46059.045 | C14: U0010 | D14: 60127073822 | F14: 蜜桃爆柠茶霸王桶 | G14: ZCH978601 | H14: 46089.045 | I14: 待发送 | K14: 未核销

Sheet 统计仪表板
A1: 📊 抽奖系统数据仪表板
A3: 📈 核心指标 | D3: 🏆 奖品发放TOP5
A4: 总注册用户 | B4: =COUNTA('用户数据'!A:A)-1 -> 0 | D4: 奖品名称 | E4: 发放数量
A5: 今日新用户 | B5: =COUNTIF('用户数据'!E:E,">="&TODAY()) -> #REF!
A6: 总抽奖次数 | B6: =COUNTA('中奖记录 1'!A:A)-1 -> 0
A7: 今日抽奖 | B7: =COUNTIF('中奖记录 1'!B:B,">="&TODAY()) -> #REF!
A8: 已核销数 | B8: =COUNTIF('中奖记录 1'!K:K,"已核销") -> #REF!
A9: 待核销数 | B9: =COUNTIF('中奖记录 1'!K:K,"未核销") -> #REF!
A10: 核销率 | B10: =IF(B7>0,B8/B7,0) -> #REF!
A11: 总邀请数 | B11: =COUNTA('邀请记录'!A:A)-1 -> 3
A14: ⚠️ 库存预警 (剩余<5)
A15: 奖品名称 | B15: 剩余库存

Sheet 邀请记录
A1: 邀请ID | B1: 邀请时间 | C1: 邀请人手机 | D1: 邀请人姓名 | E1: 被邀请人手机 | F1: 被邀请人姓名 | G1: 邀请人获得积分 | H1: 状态
A2: I001 | B2: 46046.669 | C2: 60123456789 | D2: 张三 | E2: 60198765432 | F2: 李四 | G2: 1 | H2: 成功
A3: I002 | B3: 46047.417 | C3: 60123456789 | D3: 张三 | E3: 60112233445 | F3: 王五 | G3: 1 | H3: 成功
A4: I003 | B4: 46047.625 | C4: 60123456789 | D4: 张三 | E4: 65912345678 | F4: Rachel | G4: 1 | H4: 成功

Sheet 员工账号
A1: 员工ID | B1: 员工姓名 | C1: 账号 | D1: 密码 | E1: 角色 | F1: 状态 | G1: 创建时间 | H1: 最后登录
A2: S001 | B2: 老板 | C2: boss | D2: 888888 | E2: Admin | F2: 启用 | G2: 46023 | H2: 46058.955
A3: S002 | B3: 经理小王 | C3: manager | D3: 123456 | E3: Manager | F3: 启用 | G3: 46023 | H3: 46049.417
A4: S003 | B4: 员工小李 | C4: staff1 | D4: 111111 | E4: Staff | F4: 启用 | G4: 46037 | H4: 46048.75
A5: S004 | B5: 员工小张 | C5: staff2 | D5: 222222 | E5: Staff | F5: 启用 | G5: 46037
A6: S005 | B6: eric | C6: 1002 | D6: 2001 | E6: Manager | F6: 启用 | G6: 46057.817
A7: S006 | B7: 1009 | C7: 1009 | D7: 9001 | E7: Manager | F7: 启用 | G7: 46057.817
A8: S007 | B8: ying xin | C8: 1004 | D8: 4001 | E8: Staff | F8: 启用 | G8: 46057.818

Sheet 系统设置
A1: 配置项 | B1: 配置值 | C1: 说明
A2: storeName | B2: 张崇会火锅 | C2: 店铺名称
A3: storeBranch | B3: 百万镇分店 | C3: 分店名称
A4: eventTitle | B4: 🐴 2026马年新春抽奖 | C4: 活动标题
A5: eventStart | B5: 2026-01-15 | C5: 活动开始日期
A6: eventEnd | B6: 2026-02-28 | C6: 活动结束日期
A7: dailyDrawLimit | B7: 3 | C7: 每日抽奖上限
A8: pointsPerDraw | B8: 1 | C8: 每次抽奖消耗积分
A9: pointsFirstRegister | B9: 1 | C9: 首次注册赠送积分
A10: pointsPerInvite | B10: 1 | C10: 邀请好友获得积分
A11: codePrefix | B11: ZCH | C11: 验证码前缀
A12: codeExpireDays | B12: 30 | C12: 验证码有效天数
... A14: waDelayHours | B14: 24 | C14: WhatsApp发送延迟(小时)
A15: waApiKey | C15: WhatsApp API Key
A16: waPhoneId | C16: WhatsApp Phone Number ID
A17: waTemplate | B17: 【张崇会火锅】恭喜您中奖！ 奖品：{prize} 验证码：{code} 有效期至：{expiry} 请到店出示验证码兑换。 | C17: WhatsApp消息模板
A18: bgmUrl | B18: https://example.com/bgm.mp3 | C18: 背景音乐URL
A19: spinSound | B19: https://example.com/spin.mp3 | C19: 转盘音效URL
A20: winSound | B20: https://example.com/win.mp3 | C20: 中奖音效URL
A21: grandWinSound | B21: https://example.com/grand.mp3 | C21: 大奖音效URL
A22: redeemDays | B22: 周一,周二,周三,周四 | C22: 可兑换日期
A23: redeemType | B23: 仅限堂食 | C23: 兑换方式
A24: stockAlertThreshold | B24: 5 | C24: 库存预警阈值
A25: bgMusicUrl | B25: https://drive.google.com/uc?export=download&id=1-9z81kGDKQxPnyfeWd8RvQ5HCXz7MeUs | C25: 背景音乐URL
A26: firecrackerUrl | C26: 鞭炮音效URL
A27: musicEnabled | B27: TRUE | C27: 是否启用音乐

Sheet 操作日志
A1: 日志ID | B1: 时间 | C1: 操作员 | D1: 操作员ID | E1: 动作类型 | F1: 详细内容 | G1: IP地址
A2: L001 | B2: 46046.669 | C2: System | E2: 用户注册 | F2: 新用户注册: 60123456789 (张三)
A3: L002 | B3: 46046.669 | C3: System | E3: 邀请成功 | F3: 60123456789 邀请 60198765432, 获得1积分
A4: L003 | B4: 46049.441 | C4: System | E4: 抽奖 | F4: 60123456789 抽中 特级肥牛 (ZCH954787)
A5: L004 | B5: 46049.5 | C5: Boss | D5: S001 | E5: 核销 | F5: 核销成功: ZCH954787 (特级肥牛) | G5: 192.168.1.1
A6: L005 | B6: 46049.667 | C6: Boss | D6: S001 | E6: 登录 | F6: 管理员登录成功 | G6: 192.168.1.1
A7: L0006 | B7: 46054.248 | C7: 老板 | D7: Admin | E7: 登录 | F7: 管理员登录
A8: L0007 | B8: 46054.248 | C8: 老板 | D8: Admin | E8: 登录 | F8: 管理员登录
A9: L0008 | B9: 46054.251 | C9: 老板 | D9: Admin | E9: 登录 | F9: 管理员登录
A10: L0009 | B10: 46054.252 | C10: System | E10: 用户注册 | F10: 新用户: 60167229332
A11: L0010 | B11: 46054.252 | C11: System | E11: 抽奖 | F11: 60167229332 抽中 五花肉 (ZCH329639)
A12: L0011 | B12: 46054.253 | C12: 老板 | D12: Admin | E12: WhatsApp发送 | F12: 发送: ZCH329639 -> 60167229332
A13: L0012 | B13: 46054.259 | C13: System | E13: 用户注册 | F13: 新用户: 60167826207
A14: L0013 | B14: 46054.259 | C14: System | E14: 抽奖 | F14: 60167826207 抽中 多巴胺绵绵冰 (ZCH727226)
A15: L0014 | B15: 46054.259 | C15: 老板 | D15: Admin | E15: WhatsApp发送 | F15: 发送: ZCH727226 -> 60167826207
A16: L0015 | B16: 46054.264 | C16: System | E16: 抽奖 | F16: 60167229332 抽中 暴打柠檬茶 (ZCH554855)
A17: L0016 | B17: 46054.264 | C17: System | E17: 抽奖 | F17: 60167229332 抽中 暴打柠檬茶 (ZCH675231)
A18: L0017 | B18: 46054.271 | C18: System | E18: 用户注册 | F18: 新用户: 60167229331
A19: L0018 | B19: 46054.271 | C19: System | E19: 抽奖 | F19: 60167229331 抽中 蜜桃爆柠茶霸王桶 (ZCH498452)
A20: L0019 | B20: 46054.287 | C20: 老板 | D20: Admin | E20: 登录 | F20: 管理员登录
A21: L0020 | B21: 46054.287 | C21: Admin | E21: 更新音乐设置 | F21: 背景音乐: 默认
A22: L0021 | B22: 46054.289 | C22: Admin | E22: 更新音乐设置 | F22: 背景音乐: 已设置
A23: L0022 | B23: 46054.29 | C23: Admin | E23: 更新音乐设置 | F23: 背景音乐: 已设置
A24: L0023 | B24: 46054.29 | C24: Admin | E24: 更新音乐设置 | F24: 背景音乐: 已设置
A25: L0024 | B25: 46054.291 | C25: Admin | E25: 更新音乐设置 | F25: 背景音乐: 已设置
A26: L0025 | B26: 46054.291 | C26: Admin | E26: 更新音乐设置 | F26: 背景音乐: 已设置
A27: L0026 | B27: 46054.299 | C27: 老板 | D27: Admin | E27: 登录 | F27: 管理员登录
A28: L0027 | B28: 46054.3 | C28: Admin | E28: 更新音乐设置 | F28: 背景音乐: 已设置
A29: L0028 | B29: 46054.3 | C29: Admin | E29: 更新音乐设置 | F29: 背景音乐: 已设置
A30: L0029 | B30: 46054.3 | C30: Admin | E30: 更新音乐设置 | F30: 背景音乐: 已设置
A31: L0030 | B31: 46054.301 | C31: Admin | E31: 更新音乐设置 | F31: 背景音乐: 已设置
A32: L0031 | B32: 46054.302 | C32: Admin | E32: 更新音乐设置 | F32: 背景音乐: 已设置
A33: L0032 | B33: 46054.302 | C33: Admin | E33: 更新音乐设置 | F33: 背景音乐: 已设置
A34: L0033 | B34: 46054.761 | C34: 老板 | D34: Admin | E34: 登录 | F34: 管理员登录
A35: L0034 | B35: 46054.761 | C35: 老板 | D35: Admin | E35: 登录 | F35: 管理员登录
A36: L0035 | B36: 46055.888 | C36: System | E36: 用户注册 | F36: 新用户: 60167997281
A37: L0036 | B37: 46055.888 | C37: System | E37: 抽奖 | F37: 60167997281 抽中 五花肉 (ZCH437192)
A38: L0037 | B38: 46055.889 | C38: System | E38: 抽奖 | F38: 60167229332 抽中 老式红糖冰豆花 (ZCH691275)
A39: L0038 | B39: 46055.89 | C39: 老板 | D39: Admin | E39: 登录 | F39: 管理员登录
A40: L0039 | B40: 46055.891 | C40: 老板 | D40: Admin | E40: WhatsApp发送 | F40: 发送: ZCH437192 -> 60167997281
...
